{
  "refpalette": "lcmt:factory_common",
  "xsize": 16,
  "zsize": 16,
  "slices": [
    [
      "                ",
      "                ",
      "  qrqrqrqrqrqr  ",
      "  r          q  ",
      "  q          r  ",
      "  r          q  ",
      "  q          r  ",
      "  r          q  ",
      "  q          r  ",
      "  r          q  ",
      "  q          r  ",
      "  r          q  ",
      "  q          r  ",
      "  rqrqrqrqrqrq  ",
      "                ",
      "                "
    ],
    [
      "                ",
      "                ",
      "                ",
      "                ",
      "     %kQQQQQ    ",
      "      kQWWWQ    ",
      "    minecraft:polished_deepslateQ:WWQ    ",
      "    u kQWWWQ    ",
      "    u kQWWWQ    ",
      "    minecraft:polished_deepslateQ:WWQ    ",
      "    % kQWWWQ    ",
      "      kQQQQQ    ",
      "                ",
      "                ",
      "                ",
      "                "
    ],
    [
      "                ",
      "                ",
      "                ",
      "                ",
      "                ",
      "                ",
      "    + +u:  %    ",
      "    +  %        ",
      "    +           ",
      "    + +u:       ",
      "                ",
      "                ",
      "                ",
      "                ",
      "                ",
      "                "
    ],
    [
      "                ",
      "                ",
      "                ",
      "                ",
      "                ",
      "                ",
      "      __        ",
      "                ",
      "                ",
      "      __        ",
      "                ",
      "                ",
      "                ",
      "                ",
      "                ",
      "                "
    ],
    [
      "                ",
      "                ",
      "                ",
      "                ",
      "                ",
      "                ",
      "                ",
      "                ",
      "                ",
      "                ",
      "                ",
      "                ",
      "                ",
      "                ",
      "                ",
      "                "
    ]
  ]
}
